File: examples/data/5D.txt
File Path: C:\Users\Prof\Desktop\Ghirardini\Test Run 83 06-11-2019 09 54 36\DAQ- Crosshead; … - (Timed).txt
Test: MTS EM Tension (Extensometer-Crosshead_limit)_concli_11032019
Test Run: Test Run 83
Date: 06/11/2019 09:45:38


_Extension 	_Load 	_Time 	_Strain1
mm	kN	sec	mm
-0,000978064008450019	0,0116459608078003	0,129999995231628	0,00385194562113611
-0,00749849095882382	0,0202538585662842	0,529999971389771	0,00606073945164098
-0,0141586415338679	0,0291956348419189	0,930000007152557	0,00850868764246115
-0,020818792108912	0,0378062515258789	1,33000004291534	0,0107002133518108
-0,027432368369773	0,0468316535949707	1,73000001907349	0,0129149502754444
-0,034045944630634	0,0557407455444336	2,13000011444092	0,0149588850035798
-0,040659520891495	0,0642549591064453	2,52999997138977	0,0174103715835372
-0,0473196741950233	0,0731608276367188	2,9300000667572	0,0196507771761389
-0,0540263936272822	0,081953239440918	3,32999992370605	0,0216530406760285
-0,0606865469308104	0,090249870300293	3,73000001907349	0,0240431782003725
-0,0673001268296503	0,0989058456420898	4,13000011444092	0,0262038920482155
-0,074006849899888	0,107550361633301	4,53000020980835	0,0286391223198734
-0,0807135729701258	0,115874671936035	4,92999982833862	0,0307344271277543
-0,0873271492309868	0,124175254821777	5,32999992370605	0,0328278765664436
-0,0939407254918478	0,132351287841797	5,73000001907349	0,035143100831192
-0,100647448562086	0,140732330322266	6,13000011444092	0,0373100629076362
-0,107261024822947	0,149244293212891	6,53000020980835	0,0394188755308278
-0,113921181764454	0,157704406738281	6,92999982833862	0,0419424759456888
-0,120581331430003	0,165436965942383	7,32999992370605	0,0439646064478438
-0,127194914966822	0,17336018371582	7,73000001907349	0,0462483112642076
-0,133855064632371	0,181549621582031	8,13000011444092	0,0487010584038217
-0,14051521429792	0,189473831176758	8,52999973297119	0,050659120461205
-0,14717536396347	0,197386672973633	8,93000030517578	0,0529423195985146
-0,15388207975775	0,204959487915039	9,32999992370605	0,0550651275261771
-0,160542229423299	0,212841796875	9,72999954223633	0,0574077166675124
-0,16724894521758	0,220511474609375	10,1300001144409	0,0596447207499295
-0,173955675563775	0,228494842529297	10,5299997329712	0,0617976329522207
-0,18066240590997	0,236279190063477	10,9300003051758	0,064005253079813
-0,187275974894874	0,24366471862793	11,3299999237061	0,0662125967210159
-0,193889558431692	0,251183441162109	11,7299995422363	0,0686368148308247
-0,200549708097242	0,258442565917969	12,1300001144409	0,0705171769368462
-0,207256438443437	0,266259246826172	12,5299997329712	0,0729808089090511
-0,214009734918363	0,273597442626953	12,9300003051758	0,0752310734242201
-0,220669884583913	0,280891143798828	13,3299999237061	0,0775061052991077
-0,227283468120731	0,287907165527344	13,7299995422363	0,0795875530457124
-0,233897037105635	0,295053131103516	14,1300001144409	0,0817245381767862
-0,240603752899915	0,302497406005859	14,5299997329712	0,0837165789562278
-0,247357063926756	0,309367797851563	14,9300003051758	0,0859999272506684
-0,253970647463575	0,316442291259766	15,3299999237061	0,0884971377672628
-0,260584201896563	0,323265258789063	15,7299995422363	0,0903559339349158
-0,267244380665943	0,330108459472656	16,1299991607666	0,0925484928302467
-0,273857964202762	0,336814788818359	16,5300006866455	0,0943937557167374
-0,280471489531919	0,343215911865234	16,9300003051758	0,0968218082562089
-0,287131668301299	0,349908721923828	17,3299999237061	0,0987730600172654
-0,293791817966849	0,356356567382813	17,7299995422363	0,101144840300549
-0,30054512899369	0,362894866943359	18,1299991607666	0,103186801425181
-0,30725184478797	0,368094390869141	18,5300006866455	0,104971528344322
-0,31391199445352	0,336034301757813	18,9300003051758	0,0976753872237168
-0,320572144119069	0,306976470947266	19,3299999237061	0,0904286353033967
-0,32727888901718	0,311798797607422	19,7299995422363	0,0917375800781883
-0,334032170940191	0,316851013183594	20,1299991607666	0,0928667577682063
-0,34069232060574	0,321603485107422	20,5300006866455	0,094244911451824
-0,347259308909997	0,325866546630859	20,9300003051758	0,095479488663841
-0,353872892446816	0,330435302734375	21,3299999237061	0,096571195172146
-0,360626203473657	0,334587799072266	21,7299995422363	0,0977070594672114
-0,367286353139207	0,338921447753906	22,1299991607666	0,0989196705631912
-0,373993068933487	0,343265197753906	22,5300006866455	0,100500648841262
-0,380606652470306	0,345804748535156	22,9300003051758	0,101027777418494
-0,387220236007124	0,337650085449219	23,3299999237061	0,0992371060419828
-0,393880356568843	0,341779022216797	23,7299995422363	0,100424738775473
-0,400587101466954	0,345327056884766	24,1299991607666	0,101333411294036
-0,407293817261234	0,348960235595703	24,5300006866455	0,102397461887449
-0,413860834669322	0,352162139892578	24,9300003051758	0,103402438980993
-0,420427822973579	0,355478485107422	25,3299999237061	0,104367223684676
-0,427181134000421	0,359103088378906	25,7299995422363	0,105352941318415
-0,43384128366597	0,362468170166016	26,1299991607666	0,106297935417388
-0,44054799946025	0,366001861572266	26,5300006866455	0,107522595499177
-0,44720817822963	0,369038452148438	26,9300003051758	0,10840857430594
-0,45391489402391	0,372090423583984	27,3299999237061	0,109346539829858
-0,46062160981819	0,375433959960938	27,7299995422363	0,110373854113277
-0,467328325612471	0,378670654296875	28,1299991607666	0,111521920189261
-0,474035041406751	0,382015228271484	28,5300006866455	0,112463589175604
-0,480695220176131	0,385295013427734	28,9300003051758	0,113600654003676
-0,487355340737849	0,388628387451172	29,3299999237061	0,11460007954156
-0,494015519507229	0,391765991210938	29,7299995422363	0,115997732791584
-0,500675698276609	0,394638000488281	30,1299991607666	0,116831484774593
-0,507242686580867	0,397972869873047	30,5300006866455	0,118075819045771
-0,513902807142586	0,401214263916016	30,9300003051758	0,119260366773233
-0,520609552040696	0,404526184082031	31,3299999237061	0,120307500765193
-0,527223106473684	0,407950164794922	31,7299995422363	0,121424367534928
-0,533929851371795	0,411121398925781	32,1300010681152	0,122585392091423
-0,540543464012444	0,414358856201172	32,5299987792969	0,123703677672893
-0,547250150702894	0,418393188476563	32,9300003051758	0,125016827951185
-0,553956837393343	0,421691223144531	33,3300018310547	0,126284474390559
-0,560570391826332	0,425025115966797	33,7299995422363	0,127405583043583
-0,567184004466981	0,428603942871094	34,1300010681152	0,128839950775728
-0,573844183236361	0,432034820556641	34,5299987792969	0,129986074171029
-0,580504303798079	0,435591644287109	34,9300003051758	0,131062828586437
-0,587257614824921	0,439185577392578	35,3300018310547	0,132454937556759
-0,594057491980493	0,442692260742188	35,7299995422363	0,133733468828723
-0,600671046413481	0,445724182128906	36,1300010681152	0,134872723720036
-0,607238034717739	0,449090911865234	36,5299987792969	0,135966882226057
-0,613944779615849	0,452525482177734	36,9300003051758	0,13728930207435
-0,620698090642691	0,455792022705078	37,3300018310547	0,138623654493131
-0,627404835540801	0,459103393554688	37,7299995422363	0,139791867695749
-0,63401844818145	0,462616760253906	38,1300010681152	0,140989941428415
-0,640632002614439	0,465986755371094	38,5299987792969	0,142189688631333
-0,647292123176157	0,469396392822266	38,9300003051758	0,143435623613186
-0,653905677609146	0,472572387695313	39,3300018310547	0,144913370604627
-0,660565856378526	0,475774017333984	39,7299995422363	0,146176636917517
-0,667226035147905	0,479463134765625	40,1300010681152	0,147430226206779
-0,673839589580894	0,483130249023438	40,5299987792969	0,148605962749571
-0,680499710142612	0,486111572265625	40,9300003051758	0,149802945088595
-0,687206455040723	0,489905914306641	41,3300018310547	0,151175714563578
-0,693866633810103	0,493004272460938	41,7299995422363	0,152501001139171
-0,700526754371822	0,496440521240234	42,1300010681152	0,153617918840609
-0,707233499269933	0,499954223632813	42,5299987792969	0,154911074787378
-0,713940185960382	0,503209381103516	42,9300003051758	0,15600751794409
-0,720600364729762	0,506476959228516	43,3300018310547	0,157413523993455
-0,72721391916275	0,509866088867188	43,7299995422363	0,158918774104677
-0,73387409793213	0,513357055664063	44,1300010681152	0,160109542775899
-0,74058078462258	0,516366394042969	44,5299987792969	0,161532676429488
-0,74724096339196	0,519985717773438	44,9300003051758	0,162715979968198
-0,75399421621114	0,523417053222656	45,3300018310547	0,164127355674282
-0,760607828851789	0,52673876953125	45,7299995422363	0,16515000606887
-0,767221383284777	0,530000061035156	46,1300010681152	0,166488345712423
-0,773928128182888	0,533375183105469	46,5299987792969	0,167913123732433
-0,780681439209729	0,53668408203125	46,9300003051758	0,169188395375386
-0,787341617979109	0,539850158691406	47,3300018310547	0,170525090652518
-0,793861981946975	0,543216125488281	47,7299995422363	0,171718405908905
-0,800522160716355	0,546253540039063	48,1300010681152	0,173190244822763
-0,807182339485735	0,550064086914063	48,5299987792969	0,174299580976367
-0,813842460047454	0,553214599609375	48,9300003051758	0,175843524630181
-0,820549204945564	0,556512573242188	49,3300018310547	0,177036199602298
-0,827209325507283	0,559843139648438	49,7299995422363	0,178473215783015
-0,833822879940271	0,563322082519531	50,1300010681152	0,179794646101072
-0,840529624838382	0,56660986328125	50,5299987792969	0,181041919859126
-0,847189803607762	0,569995056152344	50,9300003051758	0,182647549081594
-0,853896490298212	0,57309765625	51,3300018310547	0,183880038093776
-0,860556669067591	0,576674682617188	51,7299995422363	0,185247175977565
-0,867216847836971	0,579881042480469	52,1300010681152	0,186617049621418
-0,873923534527421	0,583207885742188	52,5299987792969	0,187807978363708
-0,880630279425532	0,586392395019531	52,9300003051758	0,189310318091884
-0,887243892066181	0,589527954101563	53,3300018310547	0,19067527318839
-0,893810880370438	0,592687561035156	53,7299995422363	0,191918108612299
-0,900564133189619	0,59625341796875	54,1300010681152	0,193369502085261
-0,907270819880068	0,599479125976563	54,5299987792969	0,194703708984889
-0,913977564778179	0,602641418457031	54,9300003051758	0,196255772607401
-0,920591177418828	0,6058359375	55,3300018310547	0,197485598619096
-0,927297864109278	0,60935302734375	55,7299995422363	0,198814959730953
-0,933911418542266	0,612266235351563	56,1300010681152	0,200195237994194
-0,940571597311646	0,6156806640625	56,5299987792969	0,201734073925763
-0,947231776081026	0,619004150390625	56,9300003051758	0,202966111828573
-0,953845330514014	0,621963562011719	57,3300018310547	0,20421200315468
-0,960412318818271	0,625164306640625	57,7299995422363	0,205650183488615
-0,967119121924043	0,628406677246094	58,1300010681152	0,207231700187549
-0,973825808614492	0,631782897949219	58,5299987792969	0,208626297535375
-0,980485929176211	0,635189575195313	58,9300003051758	0,210133250220679
-0,98714604973793	0,638163818359375	59,3300018310547	0,211340593523346
-0,993806286714971	0,641298583984375	59,7299995422363	0,212852173717692
-1,00051297340542	0,644653625488281	60,1300010681152	0,214146537473425
-1,00721966009587	0,647689514160156	60,5299987792969	0,215551888686605
-1,01397302933037	0,65111669921875	60,9300003051758	0,217143417103216
-1,02063314989209	0,654176513671875	61,3300018310547	0,218456058064476
-1,02720013819635	0,657338562011719	61,7299995422363	0,219784807995893
-1,0339068248868	0,660234313964844	62,1300010681152	0,221277063246816
-1,04061362799257	0,663354614257813	62,5299987792969	0,222781673073769
-1,04722718242556	0,666878784179688	62,9300003051758	0,22429958335124
-1,0538874194026	0,669871276855469	63,3300018310547	0,225522031541914
-1,06064055580646	0,672861877441406	63,7299995422363	0,226923773880117
-1,06725422665477	0,67572412109375	64,129997253418	0,228349861572497
-1,07386778108776	0,678996337890625	64,5299987792969	0,22983418602962
-1,08052790164948	0,6822021484375	64,9300003051758	0,231231300858781
-1,08714145608246	0,685219970703125	65,3300018310547	0,232506587053649
-1,09384825918823	0,688311462402344	65,7300033569336	0,234269347856753
-1,10046181362122	0,691126953125	66,129997253418	0,235537183471024
-1,10712193418294	0,6941064453125	66,5299987792969	0,236910054809414
-1,11373560503125	0,697282775878906	66,9300003051758	0,238552980590612
-1,12039560917765	0,700393493652344	67,3300018310547	0,240112713072449
-1,12710241228342	0,7036962890625	67,7300033569336	0,241607340285555
-1,13380909897387	0,706521118164063	68,129997253418	0,242895854171366
-1,14046933595091	0,709596008300781	68,5299987792969	0,244582130108029
-1,14717602264136	0,712626098632813	68,9300003051758	0,245915871346369
-1,15383614320308	0,715483947753906	69,3300018310547	0,247488933382556
-1,16063607856631	0,718730590820313	69,7300033569336	0,248839060077444
-1,16734276525676	0,721946899414063	70,129997253418	0,250483310082927
-1,17395643610507	0,725048156738281	70,5299987792969	0,251769961323589
-1,18056987412274	0,728070251464844	70,9300003051758	0,253497419180349
-1,18723011109978	0,731401184082031	71,3300018310547	0,255050807027146
-1,19384354911745	0,73429833984375	71,7300033569336	0,25658289087005
-1,20055035222322	0,737754272460938	72,129997253418	0,258054758887738
-1,20721058920026	0,740822143554688	72,5299987792969	0,2598371647764
-1,21382402721792	0,7437578125	72,9300003051758	0,261294102529064
-1,22043769806623	0,747149597167969	73,3300018310547	0,262723653577268
-1,22709781862795	0,750070190429688	73,7300033569336	0,264372793026268
-1,23380462173373	0,753127563476563	74,129997253418	0,26576645905152
-1,24046474229544	0,756170959472656	74,5299987792969	0,267498311586678
-1,24712474644184	0,759110534667969	74,9300003051758	0,269108451902866
-1,25387811567634	0,762331359863281	75,3300018310547	0,27067365590483
-1,2604451039806	0,765082336425781	75,7300033569336	0,272172590484843
-1,26701209228486	0,768233642578125	76,129997253418	0,273846584605053
-1,27376546151936	0,771194030761719	76,5299987792969	0,275406171567738
-1,28047214820981	0,774064025878906	76,9300003051758	0,277139886748046
-1,28717883490026	0,777023864746094	77,3300018310547	0,278708117548376
-1,29393220413476	0,780187561035156	77,7300033569336	0,280191597994417
-1,30059232469648	0,782944030761719	78,129997253418	0,281925516901538
-1,30715931300074	0,785979431152344	78,5299987792969	0,283623463474214
-1,31391268223524	0,788864440917969	78,9300003051758	0,285081245237961
-1,32061936892569	0,791613586425781	79,3300018310547	0,286684691673145
-1,32727960590273	0,794694763183594	79,7300033569336	0,288371811620891
-1,33384659420699	0,797505676269531	80,129997253418	0,289805553620681
-1,34041358251125	0,80044921875	80,5299987792969	0,291632721200585
-1,3471202692017	0,8031826171875	80,9300003051758	0,293150311335921
-1,35382695589215	0,806244384765625	81,3300018310547	0,294949451927096
-1,36048707645386	0,808878173828125	81,7300033569336	0,296544516459107
-1,36710074730217	0,811719116210938	82,129997253418	0,298081169603392
-1,37376086786389	0,814530334472656	82,5299987792969	0,29974416247569
-1,38042098842561	0,817395080566406	82,9300003051758	0,301463500363752
-1,38717424124479	0,820008239746094	83,3300018310547	0,303013919619843
-1,39388104435056	0,82281591796875	83,7300033569336	0,304776447592303
-1,40044803265482	0,825647521972656	84,129997253418	0,306421599816531
-1,40706158708781	0,828370178222656	84,5299987792969	0,308229849906638
-1,41376827377826	0,830982116699219	84,9300003051758	0,309699476929381
-1,42052164301276	0,834151916503906	85,3300018310547	0,311403069645166
-1,4271818799898	0,836672668457031	85,7300033569336	0,313253549393266
-1,43379531800747	0,839831176757813	86,129997253418	0,314902950776741
-1,44050200469792	0,842284545898438	86,5299987792969	0,316692137857899
-1,44716224167496	0,845317138671875	86,9300003051758	0,318651203997433
-1,45391549449414	0,847964233398438	87,3300018310547	0,320105755236
-1,46052904892713	0,850748168945313	87,7300033569336	0,321927422191948
-1,46718928590417	0,853354614257813	88,129997253418	0,323754502460361
-1,47389597259462	0,856281494140625	88,5299987792969	0,3254902549088
-1,48055609315634	0,859030334472656	88,9300003051758	0,327278743498027
-1,48721621371806	0,861520690917969	89,3300018310547	0,328887428622693
-1,49378320202231	0,864319519042969	89,7300033569336	0,33071989309974
-1,50035019032657	0,866685424804688	90,129997253418	0,332448456902057
-1,50710355956107	0,869509094238281	90,5299987792969	0,334362033754587
-1,51376379653811	0,87225244140625	90,9300003051758	0,335817429004237
-1,52042391709983	0,874643188476563	91,3300018310547	0,337754929205403
-1,52708403766155	0,877030578613281	91,7300033569336	0,339339429046959
-1,53379084076732	0,879746337890625	92,129997253418	0,341181992553175
-1,54049752745777	0,882106689453125	92,5299987792969	0,343089050147682
-1,54715764801949	0,88498291015625	92,9300003051758	0,344908301485702
-1,55377120245248	0,887433532714844	93,3300018310547	0,346786167938262
-1,5604313230142	0,890074768066406	93,7300033569336	0,348596251569688
-1,56709144357592	0,892699829101563	94,129997253418	0,350265268934891
-1,57379824668169	0,895289611816406	94,5299987792969	0,352152506820858
-1,58050504978746	0,897665100097656	94,9300003051758	0,353886192897335
-1,58721173647791	0,9001416015625	95,3300018310547	0,355769268935546
-1,59382517449558	0,902546081542969	95,7300033569336	0,35769323585555
-1,60048541147262	0,904950256347656	96,129997253418	0,359484081855044
-1,60719221457839	0,907446411132813	96,5299987792969	0,36132411332801
-1,61389890126884	0,910190551757813	96,9300003051758	0,363211496733129
-1,62051245570183	0,912444763183594	97,3300018310547	0,365136336768046
-1,62717257626355	0,914806457519531	97,7300033569336	0,367052882211283
-1,63383269682527	0,917137878417969	98,129997253418	0,368921784684062
-1,64049293380231	0,919598693847656	98,5299987792969	0,370704830856994
-1,64705992210656	0,921634399414063	98,9300003051758	0,372712645912543
-1,65372004266828	0,924205017089844	99,3300018310547	0,37464001798071
-1,66033359710127	0,926883178710938	99,7300033569336	0,376386742573231
-1,66704040020704	0,929152954101563	100,129997253418	0,378293043468148
-1,67379365302622	0,931542236328125	100,529998779297	0,380471290554851
-1,68045377358794	0,93395703125	100,930000305176	0,382089958293363
-1,68711401056498	0,936168701171875	101,330001831055	0,384144164854661
-1,6937741311267	0,938814758300781	101,730003356934	0,386160769267008
-1,70052738394588	0,941014465332031	102,129997253418	0,388129847124219
-1,70723418705165	0,943418212890625	102,529998779297	0,390220171539113
-1,71389419119805	0,945717163085938	102,930000305176	0,392234767787158
-1,72055442817509	0,947776123046875	103,330001831055	0,394133647205308
-1,72721454873681	0,950081176757813	103,730003356934	0,395968032535166
-1,73382821958512	0,952222045898438	104,129997253418	0,398028816562146
-1,74053490627557	0,954603454589844	104,529998779297	0,399983051465824
-1,74719502683729	0,956813171386719	104,930000305176	0,402099656639621
-1,75380858127028	0,958765319824219	105,330001831055	0,404134363634512
-1,760468701832	0,96101171875	105,730003356934	0,406081962864846
-1,76717538852245	0,963343444824219	106,129997253418	0,408133579185233
-1,77388230804354	0,965746398925781	106,529998779297	0,410407315939665
-1,7804492963478	0,967733581542969	106,930000305176	0,412222580052912
-1,78710941690952	0,969864074707031	107,330001831055	0,414246605942026
-1,7937229713425	0,971962646484375	107,730003356934	0,41633629007265
-1,80038309190422	0,974266967773438	108,129997253418	0,418385228840634
-1,80708977859467	0,976390808105469	108,529998779297	0,420398864662275
-1,81370344944298	0,97838330078125	108,930000305176	0,422307697590441
-1,82041013613343	0,980780578613281	109,330001831055	0,424636586103588
-1,82711682282388	0,982947021484375	109,730003356934	0,426816230174154
-1,83382350951433	0,985101440429688	110,129997253418	0,42876586667262
-1,8405303126201	0,987520446777344	110,529998779297	0,430902611697093
-1,84723699931055	0,989371276855469	110,930000305176	0,433125853305683
-1,85389723628759	0,991247924804688	111,330001831055	0,435145106166601
-1,86060392297804	0,993692077636719	111,730003356934	0,437283626524732
-1,86731060966849	0,9955146484375	112,129997253418	0,43948256643489
-1,87383103184402	0,997480041503906	112,529998779297	0,441527052316815
-1,88039802014828	0,999507934570313	112,930000305176	0,443604309111834
-1,88710470683873	1,00149822998047	113,330001831055	0,445838202722371
-1,8938115099445	1,00343597412109	113,730003356934	0,447919388534501
-1,90051819663495	1,00537145996094	114,129997253418	0,450158811872825
-1,90708518493921	1,00758526611328	114,529998779297	0,452289212262258
-1,91374542191625	1,00951916503906	114,930000305176	0,454546621767804
-1,92049867473543	1,01125152587891	115,330001831055	0,456605950603262
-1,92711222916842	1,01310620117188	115,730003356934	0,459105358459055
-1,93381891585886	1,01512182617188	116,129997253418	0,461208226624876
-1,94038590416312	1,01689501953125	116,529998779297	0,463262404082343
-1,94704614114016	1,01876153564453	116,930000305176	0,465484976302832
-1,95375294424593	1,02067346191406	117,330001831055	0,467739708255976
-1,96050619706512	1,02265625	117,730003356934	0,469808845082298
-1,9671197514981	1,0243671875	118,129997253418	0,472104991786182
-1,97377987205982	1,02613854980469	118,529998779297	0,474476022645831
-1,98043999262154	1,02787902832031	118,930000305176	0,476530840387568
-1,98714667931199	1,02995349121094	119,330001831055	0,479060196084902
-1,99390016496181	1,03162219238281	119,730003356934	0,481149385450408
-2,00056028552353	1,033431640625	120,129997253418	0,483355746837333
-2,00722017325461	1,0352421875	120,529998779297	0,485511729493737
-2,01383396051824	1,03690344238281	120,930000305176	0,487853627419099
-2,02049408107996	1,0385	121,330001831055	0,490204314701259
-2,02715420164168	1,04046716308594	121,730003356934	0,492497347295284
-2,03376775607467	1,04203247070313	122,129997253418	0,494774605613202
-2,0403815433383	1,04398449707031	122,529998779297	0,496888998895884
-2,04713456332684	1,04556420898438	122,930000305176	0,499231915455312
-2,0537949167192	1,04726184082031	123,330001831055	0,501870876178145
-2,06045503728092	1,04903002929688	123,730003356934	0,503998890053481
-2,06706859171391	1,05089965820313	124,129997253418	0,506256939843297
-2,07372871227562	1,05198571777344	124,529998779297	0,508877797983587
-2,0804819650948	1,05386511230469	124,930000305176	0,511035264935344
-2,08714231848717	1,05547839355469	125,330001831055	0,513250823132694
-2,09380220621824	1,05681457519531	125,730003356934	0,51572744268924
-2,10041599348187	1,0586064453125	126,129997253418	0,518052605912089
-2,10707588121295	1,05992919921875	126,529998779297	0,520378176588565
-2,11373623460531	1,06148168945313	126,930000305176	0,522608170285821
-2,12048948742449	1,06323083496094	127,330001831055	0,525272102095187
-2,12710304185748	1,06497326660156	127,730003356934	0,527479045558721
-2,13376339524984	1,06641662597656	128,130004882813	0,529993034433573
-2,14047008194029	1,06809411621094	128,529998779297	0,532125530298799
-2,14717676863074	1,06962951660156	128,929992675781	0,534663035068661
-2,15393002144992	1,07124291992188	129,330001831055	0,537044019438326
-2,16049700975418	1,07282946777344	129,729995727539	0,539587577804923
-2,16711033135653	1,07476879882813	130,130004882813	0,542017864063382
-2,17377068474889	1,07588244628906	130,529998779297	0,544410606380552
-2,18043080531061	1,07735327148438	130,929992675781	0,546897412277758
-2,18709115870297	1,07884631347656	131,330001831055	0,549453950952739
-2,19375104643404	1,08065893554688	131,729995727539	0,55189395789057
-2,2003180347383	1,08194152832031	132,130004882813	0,554330588784069
-2,20697838813066	1,08337634277344	132,529998779297	0,557007733732462
-2,21368507482111	1,08483862304688	132,929992675781	0,559241918381304
-2,22039176151156	1,08630017089844	133,330001831055	0,56191417388618
-2,22700531594455	1,08772399902344	133,729995727539	0,564303772989661
-2,233712002635	1,08948718261719	134,130004882813	0,56706607574597
-2,24046548828483	1,09096264648438	134,529998779297	0,569577270653099
-2,2471253760159	1,09233776855469	134,929992675781	0,572144344914705
-2,25369236432016	1,09348095703125	135,330001831055	0,574800244066864
-2,26035271771252	1,09506274414063	135,729995727539	0,577581697143614
-2,26705940440297	1,09662353515625	136,130004882813	0,580022227950394
-2,27381265722215	1,09810278320313	136,529998779297	0,582735578063875
-2,28051957674325	1,09955847167969	136,929992675781	0,585224945098162
-2,28713289834559	1,10085571289063	137,330001831055	0,587884744163603
-2,29379325173795	1,10202307128906	137,729995727539	0,590239535085857
-2,30045313946903	1,10361584472656	138,130004882813	0,59312442317605
-2,30715982615948	1,10479016113281	138,529998779297	0,595764606259763
-2,31382017955184	1,10632641601563	138,929992675781	0,598488375544548
-2,3203871678561	1,10741564941406	139,330001831055	0,601132633164525
-2,32700072228909	1,10885034179688	139,729995727539	0,603617343585938
-2,3336608428508	1,11018811035156	140,130004882813	0,606430170591921
-2,34036752954125	1,11117431640625	140,529998779297	0,609059527050704
-2,34698131680489	1,11261975097656	140,929992675781	0,611914729233831
-2,35364120453596	1,11368444824219	141,330001831055	0,614769116509706
-2,36030155792832	1,11510656738281	141,729995727539	0,617235200479627
-2,36700824461877	1,116447265625	142,130004882813	0,61972055118531
-2,37371493130922	1,11778723144531	142,529998779297	0,622855499386787
-2,38042161799967	1,11926721191406	142,929992675781	0,625538872554898
-2,38712830469012	1,12049047851563	143,330001831055	0,628108391538262
-2,39378865808249	1,12147253417969	143,729995727539	0,630957947578281
-2,4004487786442	1,12244860839844	144,130004882813	0,633596035186201
-2,40715546533465	1,12382189941406	144,529998779297	0,636308861430734
-2,41376901976764	1,12495666503906	144,929992675781	0,639155623503029
-2,42042914032936	1,12607702636719	145,330001831055	0,641904014628381
-2,42718239314854	1,12729333496094	145,729995727539	0,644705025479198
-2,4338427465409	1,12821594238281	146,130004882813	0,647637934889644
-2,44045606814325	1,1291748046875	146,529998779297	0,650202564429492
-2,44702305644751	1,13061547851563	146,929992675781	0,653171096928418
-2,4537299759686	1,13179418945313	147,330001831055	0,656033575069159
-2,46039009653032	1,132990234375	147,729995727539	0,658862816635519
-2,46709678322077	1,13411657714844	148,130004882813	0,66184886964038
-2,47375713661313	1,13529626464844	148,529998779297	0,66481827525422
-2,48032412491739	1,13657836914063	148,929992675781	0,667404325213283
-2,48693744651973	1,13774426269531	149,330001831055	0,670659297611564
-2,49364413321018	1,139376953125	149,729995727539	0,673485221341252
-2,50039738602936	1,1403271484375	150,130004882813	0,676443800330162
-2,50705773942173	1,14186145019531	150,529998779297	0,679452088661492
-2,51371785998344	1,14282775878906	150,929992675781	0,682327023241669
-2,52042454667389	1,144072265625	151,330001831055	0,685583683662117
-2,52713123336434	1,14552551269531	151,729995727539	0,688517349772155
-2,53383792005479	1,14645092773438	152,130004882813	0,691881636157632
-2,54049827344716	1,14736645507813	152,529998779297	0,694578920956701
-2,54711182788014	1,14853564453125	152,929992675781	0,697549898177385
-2,55381851457059	1,14970227050781	153,330001831055	0,700698350556195
-2,56047863513231	1,15083630371094	153,729995727539	0,703818048350513
-2,56713875569403	1,15183605957031	154,130004882813	0,706920516677201
-2,57375231012702	1,15237438964844	154,529998779297	0,709895102772862
-2,58036586456001	1,15348120117188	154,929992675781	0,713092333171517
-2,58702621795237	1,15436779785156	155,330001831055	0,716373324394226
-2,59373290464282	1,15547387695313	155,729995727539	0,719425908755511
-2,6003927923739	1,15670959472656	156,130004882813	0,722606258932501
-2,60705314576626	1,15750402832031	156,529998779297	0,725687714293599
-2,61371326632798	1,15847509765625	156,929992675781	0,728664977941662
-2,62041995301843	1,15911730957031	157,330001831055	0,732088461518288
-2,62708030641079	1,16002172851563	157,729995727539	0,735118635930121
-2,63374019414186	1,16103601074219	158,130004882813	0,738387054298073
-2,64030718244612	1,16172644042969	158,529998779297	0,741533993277699
-2,64701386913657	1,16247375488281	158,929992675781	0,744598335586488
-2,6537673547864	1,16326403808594	159,330001831055	0,748061807826161
-2,66042724251747	1,16422839355469	159,729995727539	0,751357642002404
-2,66713416203856	1,16519201660156	160,130004882813	0,754140841308981
-2,67370115034282	1,16589477539063	160,529998779297	0,757647154387087
-2,680454403162	1,16692822265625	160,929992675781	0,760699796956033
-2,68720765598118	1,16765966796875	161,330001831055	0,764084397815168
-2,69386800937355	1,16863781738281	161,729995727539	0,767317076679319
-2,70048133097589	1,16921997070313	162,130004882813	0,77049876563251
-2,70714168436825	1,16996826171875	162,529998779297	0,773981737438589
-2,71375523880124	1,17096447753906	162,929992675781	0,777192763052881
-2,72041535936296	1,17147607421875	163,330001831055	0,780344184022397
-2,72712204605341	1,17217236328125	163,729995727539	0,783753930591047
-2,7337356004864	1,17297790527344	164,130004882813	0,787066295742989
-2,74034938775003	1,17367395019531	164,529998779297	0,790356658399105
-2,74705607444048	1,17450646972656	164,929992675781	0,793759943917394
-2,75376276113093	1,17512255859375	165,330001831055	0,79690886195749
-2,76042288169265	1,17602807617188	165,729995727539	0,800177629571408
-2,76708300225437	1,17647033691406	166,130004882813	0,803509901743382
-2,77369655668736	1,17725317382813	166,529998779297	0,806803349405527
-2,78040347620845	1,17782458496094	166,929992675781	0,810269615612924
-2,7871101628989	1,17846057128906	167,330001831055	0,813502294477075
-2,79372348450124	1,17891149902344	167,729995727539	0,816817337181419
-2,80033703893423	1,1796591796875	168,130004882813	0,819955777842551
-2,80709052458405	1,18022827148438	168,529998779297	0,823677750304341
-2,8137972112745	1,18106005859375	168,929992675781	0,826900417450815
-2,82050389796495	1,18164099121094	169,330001831055	0,830292236059904
-2,82711745239794	1,18210229492188	169,729995727539	0,833861937280744
-2,83382413908839	1,18278503417969	170,130004882813	0,836993218399584
-2,84053082577884	1,18366589355469	170,529998779297	0,840581662487239
-2,84723751246929	1,18429321289063	170,929992675781	0,844021502416581
-2,85389786586165	1,18475805664063	171,330001831055	0,847174553200603
-2,86046485416591	1,18516357421875	171,729995727539	0,850654032547027
-2,86703184247017	1,18541333007813	172,130004882813	0,853850273415446
-2,87373852916062	1,18621740722656	172,529998779297	0,857425678987056
-2,88039864972234	1,18684411621094	172,929992675781	0,860699277836829
-2,88710556924343	1,18765075683594	173,330001831055	0,864288012962788
-2,89371889084578	1,1879931640625	173,729995727539	0,867553346324712
-2,90042557753623	1,18864685058594	174,130004882813	0,871116179041564
-2,90703936479986	1,18926147460938	174,529998779297	0,874628778547049
-2,91365291923285	1,18963464355469	174,929992675781	0,878117338288575
-2,92045273818076	1,19012744140625	175,330001831055	0,881488143932074
-2,92706629261374	1,19049755859375	175,729995727539	0,8848708239384
-2,93377297930419	1,19138244628906	176,130004882813	0,888485577888787
-2,94043333269656	1,19171435546875	176,529998779297	0,891829549800605
-2,94714001938701	1,19250158691406	176,929992675781	0,895362580195069
-2,95375357381999	1,19273095703125	177,330001831055	0,898852129466832
-2,96046026051044	1,19338842773438	177,729995727539	0,902244937606156
-2,96712038107216	1,19378540039063	178,130004882813	0,905738677829504
-2,97382706776261	1,19429479980469	178,529998779297	0,909286667592824
-2,98053375445306	1,19472045898438	178,929992675781	0,912781863007694
-2,98714730888605	1,19526647949219	179,330001831055	0,916307442821562
-2,99380766227841	1,19578247070313	179,729995727539	0,919989484827966
-3,00051434896886	1,19585485839844	180,130004882813	0,923301791772246
-3,00717446953058	1,19644323730469	180,529998779297	0,926868175156415
-3,01378802396357	1,19675402832031	180,929992675781	0,930347538087517
-3,02035501226783	1,19688940429688	181,330001831055	0,93382503837347
-3,02701513282955	1,19764880371094	181,729995727539	0,937295902986079
-3,03372181952	1,19786547851563	182,130004882813	0,940937199629843
-3,04042873904109	1,19841247558594	182,529998779297	0,944582396186888
-3,04704206064343	1,1987060546875	182,929992675781	0,9481260785833
-3,05365584790707	1,19905798339844	183,330001831055	0,951601949054748
-3,06036253459752	1,19955065917969	183,729995727539	0,955146097112447
-3,0671157874167	1,20027282714844	184,130004882813	0,958780117798597
-3,07386904023588	1,20023718261719	184,529998779297	0,962213729508221
-3,0805291607976	1,20094311523438	184,929992675781	0,966055376920849
-3,08714271523058	1,20128063964844	185,330001831055	0,969505286775529
-3,0938028357923	1,20153857421875	185,729995727539	0,973203859757632
-3,10046318918467	1,20199633789063	186,130004882813	0,976744224317372
-3,10721644200385	1,20238647460938	186,529998779297	0,980334938503802
-3,11382999643683	1,20241870117188	186,929992675781	0,983797828666866
-3,12049011699855	1,2028662109375	187,330001831055	0,987543142400682
-3,12715023756027	1,20321618652344	187,729995727539	0,991101609542966
-3,13381059095263	1,20360815429688	188,130004882813	0,994850764982402
-3,14051727764308	1,2038466796875	188,529998779297	0,998506788164377
-3,14708426594734	1,20421069335938	188,929992675781	1,00195477716625
-3,15374415367842	1,20461071777344	189,330001831055	1,00545946042985
-3,16035794094205	1,20472448730469	189,729995727539	1,00926251616329
-3,16701782867312	1,20528601074219	190,130004882813	1,01288862060755
-3,17367818206549	1,20555407714844	190,529998779297	1,01650832220912
-3,18038486875594	1,2058974609375	190,929992675781	1,02026073727757
-3,18704498931766	1,20604077148438	191,330001831055	1,02404586505145
-3,19365854375064	1,206255859375	191,729995727539	1,02727964986116
-3,20041202940047	1,20675036621094	192,130004882813	1,0310944635421
-3,20707191713154	1,20671496582031	192,529998779297	1,0347559582442
-3,21373227052391	1,20718835449219	192,929992675781	1,03844446130097
-3,22053208947182	1,20735534667969	193,330001831055	1,04205741081387
-3,22723900899291	1,20771752929688	193,729995727539	1,04595243465155
-3,23385233059525	1,20799194335938	194,130004882813	1,04950461536646
-3,24046611785889	1,20812841796875	194,529998779297	1,05322385206819
-3,24707967229187	1,208296875	194,929992675781	1,05691514909267
-3,25373979285359	1,20857873535156	195,330001831055	1,06071843765676
-3,26044647954404	1,20862243652344	195,729995727539	1,064493204467
-3,26715316623449	1,20886706542969	196,130004882813	1,06807460542768
-3,27376672066748	1,20903771972656	196,529998779297	1,07184122316539
-3,28038027510047	1,20924731445313	196,929992675781	1,07575010042638
-3,28708696179092	1,20943969726563	197,330001831055	1,07927166391164
-3,29374708235264	1,20974572753906	197,729995727539	1,08303735032678
-3,30045400187373	1,20982788085938	198,130004882813	1,0867357486859
-3,30706732347608	1,20979406738281	198,529998779297	1,09049247112125
-3,31368111073971	1,21018090820313	198,929992675781	1,09418213833123
-3,32038779743016	1,21033984375	199,330001831055	1,09824677929282
-3,32704815082252	1,21052160644531	199,729995727539	1,10169488471001
-3,3337080385536	1,21080725097656	200,130004882813	1,10585102811456
-3,34041472524405	1,21068737792969	200,529998779297	1,10941275488585
-3,34702851250768	1,21069348144531	200,929992675781	1,1130312923342
-3,35373519919813	1,21100463867188	201,330001831055	1,11686170566827
-3,36048845201731	1,21103991699219	201,729995727539	1,12060271203518
-3,36719513870776	1,21118041992188	202,130004882813	1,12429924774915
-3,37380869314075	1,21129821777344	202,529998779297	1,12824479583651
-3,38042224757373	1,21164697265625	202,929992675781	1,13202957436442
-3,38717550039291	1,21165051269531	203,330001831055	1,13586883526295
-3,39378928765655	1,2118466796875	203,729995727539	1,13970623351634
-3,40044917538762	1,21215661621094	204,130004882813	1,14352500531822
-3,40706296265125	1,21192797851563	204,529998779297	1,14745122846216
-3,4137696493417	1,21206750488281	204,929992675781	1,15126557648182
-3,42047633603215	1,21242590332031	205,330001831055	1,15510914474726
-3,42708989046514	1,21203271484375	205,729995727539	1,15882209502161
-3,4337502438575	1,21221789550781	206,130004882813	1,16290245205164
-3,44041013158858	1,21196215820313	206,529998779297	1,16689712740481
-3,4470702521503	1,21221630859375	206,929992675781	1,17070018313825
-3,45377717167139	1,21224853515625	207,330001831055	1,17441616021097
-3,46043729223311	1,21233984375	207,729995727539	1,17862294428051
-3,4670508466661	1,21205456542969	208,130004882813	1,18218665011227
-3,47371096722782	1,21200817871094	208,529998779297	1,1860691010952
-3,48037132062018	1,21180456542969	208,929992675781	1,19023467414081
-3,48703120835125	1,21198229980469	209,330001831055	1,19422317948192
-3,4937378950417	1,2119833984375	209,729995727539	1,19807431474328
-3,50039824843407	1,21217749023438	210,130004882813	1,20201916433871
-3,5071512684226	1,21218408203125	210,529998779297	1,20582920499146
-3,51385842077434	1,2122822265625	210,929992675781	1,20986951515079
-3,52051830850542	1,21221398925781	211,330001831055	1,21372565627098
-3,52717842906713	1,21243383789063	211,729995727539	1,21791823767126
-3,5338387824595	1,21216198730469	212,130004882813	1,22190394904464
-3,54054546914995	1,21207373046875	212,529998779297	1,22563610784709
-3,54715902358294	1,21212573242188	212,929992675781	1,22972810640931
-3,55386571027339	1,21192236328125	213,330001831055	1,23384722974151
-3,56043269857764	1,21189965820313	213,729995727539	1,23756169341505
-3,5669996868819	1,21164099121094	214,130004882813	1,24177790712565
-3,57375293970108	1,21162951660156	214,529998779297	1,24570541083813
-3,5804130602628	1,21124731445313	214,929992675781	1,24938145745546
-3,58707341365516	1,21122387695313	215,330001831055	1,25358847435564
-3,59373353421688	1,21139428710938	215,729995727539	1,25772203318775
-3,60039342194796	1,21087841796875	216,130004882813	1,26158143393695
-3,60719347372651	1,21128112792969	216,529998779297	1,26565992832184
-3,61376046203077	1,21097436523438	216,929992675781	1,26974168233573
-3,62042058259249	1,21065405273438	217,330001831055	1,27378909382969
-3,62703413702548	1,21017993164063	217,729995727539	1,27787329256535
-3,63369449041784	1,21038403320313	218,130004882813	1,28151068929583
-3,64044751040637	1,210619140625	218,529998779297	1,28603493794799
-3,64720076322556	1,21066259765625	218,929992675781	1,29007373470813
-3,65386111661792	1,21015808105469	219,330001831055	1,29411381203681
-3,66042810492218	1,20950695800781	219,729995727539	1,2979197781533
-3,667181590572	1,20997619628906	220,130004882813	1,30221166182309
-3,67384147830307	1,20954211425781	220,529998779297	1,30604184232652
-3,68054816499352	1,20930236816406	220,929992675781	1,31018727552146
-3,68720851838589	1,2087626953125	221,330001831055	1,3143855612725
-3,69377550669014	1,20825646972656	221,729995727539	1,31834717467427
-3,70038882829249	1,20783862304688	222,130004882813	1,32245826534927
-3,70700261555612	1,20753088378906	222,529998779297	1,32660940289497
-3,71370930224657	1,20736828613281	222,929992675781	1,3308412162587
-3,72032285667956	1,20696752929688	223,330001831055	1,33466662373394
-3,72698297724128	1,20656555175781	223,729995727539	1,33893673773855
-3,73368989676237	1,20630346679688	224,130004882813	1,34310789871961
-3,74039658345282	1,20589819335938	224,529998779297	1,34729396086186
-3,74710327014327	1,20575805664063	224,929992675781	1,35139154735953
-3,75371659174562	1,20504760742188	225,330001831055	1,35562964715064
-3,76047007739544	1,20500317382813	225,729995727539	1,35986937675625
-3,76717676408589	1,20422973632813	226,130004882813	1,36424077209085
-3,77388368360698	1,20363317871094	226,529998779297	1,36852462310344
-3,78049700520933	1,20299682617188	226,929992675781	1,37281708884984
-3,78711055964231	1,20233898925781	227,330001831055	1,3771535595879
-3,79381724633276	1,20178930664063	227,729995727539	1,38159666676074
-3,80052416585386	1,20103759765625	228,130004882813	1,38599588535726
-3,80723085254431	1,20026525878906	228,529998779297	1,39049079734832
-3,81379784084857	1,19917321777344	228,929992675781	1,39515206683427
-3,82036506198347	1,19848754882813	229,330001831055	1,39953836333007
-3,827118081972	1,19742236328125	229,729995727539	1,40418182127178
-3,83382476866245	1,19637292480469	230,130004882813	1,40884390566498
-3,84057802148163	1,19486657714844	230,529998779297	1,41344510484487
-3,8470053113997	1,19313098144531	230,929992675781	1,41813373193145
-3,85361909866333	1,19140124511719	231,330001831055	1,42303551547229
-3,86032578535378	1,19007275390625	231,729995727539	1,4281707117334
-3,86703247204423	1,18805676269531	232,130004882813	1,43344840034842
-3,87373915873468	1,1856357421875	232,529998779297	1,43879710230976
-3,88039951212704	1,1830498046875	232,929992675781	1,44428631756455
-3,88710619881749	1,18043603515625	233,330001831055	1,45036401227117
-3,89367318712175	1,1768232421875	233,729995727539	1,45638582762331
-3,90047277323902	1,17324816894531	234,130004882813	1,46334967575967
-3,90717945992947	1,16830029296875	234,529998779297	1,47047557402402
-3,91383981332183	1,16248474121094	234,929992675781	1,4781893696636
-3,92054673284292	1,15550988769531	235,330001831055	1,4864489203319
-3,927206620574	1,14733508300781	235,729995727539	1,49561872240156
-3,93386697396636	1,13747570800781	236,130004882813	1,50599156040698
-3,94052686169744	1,12545544433594	236,529998779297	1,51714391540736
-3,94709408283234	1,1111376953125	236,929992675781	1,5299734659493
-3,95380053669214	1,0896005859375	237,330001831055	1,54724915046245
-3,96050745621324	0,766486022949219	237,729995727539	1,85412727296352
-3,96721391007304	0,761895874023438	238,130004882813	1,86009972821921
-3,97382769733667	0,768002807617188	238,529998779297	1,86186609789729
-3,98048805072904	0,773174377441406	238,929992675781	1,86333199962974
-3,98719450458884	0,777461791992188	239,330001831055	1,86474132351577
-3,99390142410994	0,781794189453125	239,729995727539	1,86606158968061
-4,00051521137357	0,786192626953125	240,130004882813	1,86765647958964
-4,00712853297591	0,789912109375	240,529998779297	1,86907197348773
-4,01378888636827	0,793585327148438	240,929992675781	1,87098293099552
-4,02049534022808	0,797680114746094	241,330001831055	1,87275919597596
-4,02720225974917	0,801148071289063	241,729995727539	1,87443010509014
-4,03381604701281	0,80472216796875	242,130004882813	1,87624944373965
-4,04052250087261	0,808344482421875	242,529998779297	1,87849602662027
-4,04718238860369	0,81155615234375	242,929992675781	1,88034016173333
-4,05388930812478	0,815083801269531	243,330001831055	1,88235705718398
-4,0606427937746	0,818046020507813	243,729995727539	1,88430666457862
-4,06730268150568	0,821017822265625	244,130004882813	1,88627862371504
-4,07396256923676	0,823711791992188	244,529998779297	1,88849645201117
-4,08057635650039	0,82627197265625	244,929992675781	1,89055758528411
-4,08714357763529	0,828356262207031	245,330001831055	1,89239508472383
-4,09389706328511	0,830461608886719	245,729995727539	1,89451244659722
-4,10050991922617	0,832268371582031	246,130004882813	1,8961422611028
-4,1071237064898	0,834205139160156	246,529998779297	1,8980415770784
-4,11383062601089	0,835184936523438	246,929992675781	1,89986918121576
-4,1205370798707	0,836324279785156	247,330001831055	1,90165254753083
-4,12719789892435	0,836736999511719	247,729995727539	1,9032001728192
-4,1338112205267	0,837190063476563	248,130004882813	1,90475129056722
-4,14047157391906	0,837082336425781	248,529998779297	1,90663803368807
-4,14717802777886	0,837046691894531	248,929992675781	1,90826039761305
-4,15383838117123	0,836584594726563	249,330001831055	1,9099764758721
-4,1604982689023	0,835418518066406	249,729995727539	1,91153201740235
-4,16711205616593	0,833430297851563	250,130004882813	1,91291596274823
-4,17377194389701	0,831934448242188	250,529998779297	1,91469409037381
-4,18047839775682	0,830114868164063	250,929992675781	1,91633217036724
-4,18723188340664	0,828085205078125	251,330001831055	1,91797420848161
-4,19389177113771	0,82590234375	251,729995727539	1,91968807484955
-4,20055259019136	0,823818786621094	252,130004882813	1,92134233657271
-4,20725904405117	0,821635192871094	252,529998779297	1,92318053450435
-4,21401206403971	0,819236145019531	252,929992675781	1,92507996689528
-4,22062585130334	0,817272399902344	253,330001831055	1,92692934069783
-4,22728573903441	0,814903564453125	253,729995727539	1,9286978058517
-4,23385296016932	0,812375732421875	254,130004882813	1,93062319885939
-4,24051331356168	0,809906616210938	254,529998779297	1,93250807933509
-4,24717320129275	0,807385559082031	254,929992675781	1,93434301763773
-4,25383355468512	0,804500183105469	255,330001831055	1,93667493294925
-4,26049390807748	0,801359558105469	255,729995727539	1,93866924382746
-4,26715379580855	0,797778625488281	256,130004882813	1,94066052790731
-4,27381414920092	0,794248046875	256,529998779297	1,94255309179425
-4,28047403693199	0,789668090820313	256,929992675781	1,94459222257137
-4,28713439032435	0,783878784179688	257,329986572266	1,94620166439563
-4,29384084418416	0,777764953613281	257,730010986328	1,94795976858586
-4,30054776370525	0,769378234863281	258,130004882813	1,94925011601299
-4,30720811709762	0,759889404296875	258,529998779297	1,94997969083488
-4,31391457095742	0,74869580078125	258,929992675781	1,95124768652022
-4,32048179209232	0,735390808105469	259,329986572266	1,95197318680584
-4,32718871161342	0,718816711425781	259,730010986328	1,95208832155913
-4,33389516547322	0,689922180175781	260,130004882813	1,94926944095641
-4,34064818546176	0,620197265625	260,529998779297	1,93054066039622
-4,34749480336905	0,0713387832641602	260,929992675781	1,65904406458139
-4,35406155884266	0,0646373138427734	261,329986572266	1,62309524603188
-4,36072191223502	0,0561901817321777	261,730010986328	1,59763777628541
-4,36733523383737	0,049406665802002	262,130004882813	1,57308287452906
-4,37408871948719	0,0427644920349121	262,529998779297	1,54636532533914
-4,38070250675082	0,0383139457702637	262,929992675781	1,5238260384649
-4,38726972788572	0,034179328918457	263,329986572266	1,50290760211647
-4,39388304948807	0,0317304439544678	263,730010986328	1,48713786620647
-4,40058996900916	0,0274560413360596	264,130004882813	1,47110188845545
-4,40729688853025	0,0228773708343506	264,529998779297	1,45822472404689
-4,41390974447131	0,0211649055480957	264,929992675781	1,44585140515119
-4,42052353173494	0,0171757869720459	265,329986572266	1,43071182537824
-4,42723045125604	0,00329314804077148	265,730010986328	1,41373323276639
-4,43398393690586	0,0018472763299942	266,130004882813	1,40298972837627
-4,4407369568944	0,00311198544502258	266,529998779297	1,97344156913459
-4,44739731028676	0,00298486590385437	266,929992675781	1,96420284919441
-4,4540106318891	0,00316887331008911	267,329986572266	1,95600651204586
-4,46071708574891	0,0032250497341156	267,730010986328	1,94875826127827
-4,46733087301254	0,00343007016181946	268,130004882813	1,94185576401651
-4,47403779253364	0,0030552716255188	268,529998779297	1,93539331667125
-4,48069768026471	0,00301702570915222	268,929992675781	1,92998512648046
-4,48735803365707	0,00289757966995239	269,329986572266	1,9247509771958
-4,49406495317817	0,00310603737831116	269,730010986328	1,91953114699572
-4,50067827478051	0,00306738018989563	270,130004882813	1,91482389345765
-4,50733862817287	0,0028224515914917	270,529998779297	1,91060348879546
-4,51399851590395	0,00290662002563477	270,929992675781	1,9064424559474
-4,52061230316758	0,00299563598632813	271,329986572266	1,90250016748905
-4,52731875702739	0,0029357545375824	271,730010986328	1,89878477249295
-4,53397911041975	0,00328611779212952	272,130004882813	1,89540581777692
-4,54063946381211	0,00311611533164978	272,529998779297	1,89195177517831
-4,54720621928573	0,00337897896766663	272,929992675781	1,88873417209834
-4,55381954088807	0,0031441342830658	273,329986572266	1,88574951607734
-4,5605730265379	0,00312162280082703	273,730010986328	1,88270723447204